<?xml version="1.0" ?>
<!-- =================================================================================== -->
<!-- |    This document was autogenerated by xacro from simple_car_integration.urdf.xacro | -->
<!-- |    EDITING THIS FILE BY HAND IS NOT RECOMMENDED                                 | -->
<!-- =================================================================================== -->
<!-- Name your robot here -->
<robot name="simple_car">
  <link name="dummy">
  </link>
  <joint name="dummy_joint" type="fixed">
    <parent link="dummy"/>
    <child link="base_link"/>
  </joint>
  <link name="base_link">
    <inertial>
      <origin rpy="0 0 0" xyz="0.42123 0.50665 0.43018"/>
      <mass value="42.886"/>
      <inertia ixx="1.0059" ixy="-0.01679" ixz="1.4641E-07" iyy="2.4369" iyz="-5.8077E-08" izz="1.7367"/>
    </inertial>
    <visual>
      <origin rpy="0 0 0" xyz="0 0 0"/>
      <geometry>
        <mesh filename="package://simple_car/meshes/base_link.STL"/>
      </geometry>
      <material name="">
        <color rgba="0.79216 0.81961 0.93333 1"/>
      </material>
    </visual>
    <collision>
      <origin rpy="0 0 0" xyz="0 0 0"/>
      <geometry>
        <mesh filename="package://simple_car/meshes/base_link.STL"/>
      </geometry>
    </collision>
  </link>
  <link name="S_R">
    <inertial>
      <origin rpy="0 0 0" xyz="3.6637E-15 0.0254 0.068366"/>
      <mass value="0.22586"/>
      <inertia ixx="0.00034327" ixy="6.532E-24" ixz="-8.5053E-19" iyy="0.00034804" iyz="7.0833E-22" izz="6.7813E-05"/>
    </inertial>
    <visual>
      <origin rpy="0 0 0" xyz="0 0 0"/>
      <geometry>
        <mesh filename="package://simple_car/meshes/S_R.STL"/>
      </geometry>
      <material name="">
        <color rgba="0 0 1 1"/>
      </material>
    </visual>
    <collision>
      <origin rpy="0 0 0" xyz="0 0 0"/>
      <geometry>
        <mesh filename="package://simple_car/meshes/S_R.STL"/>
      </geometry>
    </collision>
  </link>
  <joint name="SR_Joint" type="revolute">
    <origin rpy="1.5708 0 -0.023053" xyz="0.67855 -0.68418 0.36349"/>
    <parent link="base_link"/>
    <child link="S_R"/>
    <axis xyz="0 1 0"/>
    <limit effort="1000" lower="-3.141" upper="3.141" velocity="1000"/>
  </joint>
  <link name="Wheel_FR">
    <inertial>
      <origin rpy="0 0 0" xyz="2.3315E-15 -2.387E-15 0.03806"/>
      <mass value="2.3167"/>
      <inertia ixx="0.0074731" ixy="3.5893E-19" ixz="-1.1316E-17" iyy="0.0074731" iyz="-4.391E-18" izz="0.012704"/>
    </inertial>
    <visual>
      <origin rpy="0 0 0" xyz="0 0 0"/>
      <geometry>
        <mesh filename="package://simple_car/meshes/Wheel_FR.STL"/>
      </geometry>
      <material name="">
        <color rgba="0 0 0 1"/>
      </material>
    </visual>
    <collision>
      <origin rpy="0 0 0" xyz="0 0 0"/>
      <geometry>
        <mesh filename="package://simple_car/meshes/Wheel_FR.STL"/>
      </geometry>
    </collision>
  </link>
  <joint name="WFR" type="continuous">
    <origin rpy="0 0 -2.3643" xyz="0 0.0254 0.05084"/>
    <parent link="S_R"/>
    <child link="Wheel_FR"/>
    <axis xyz="0 0 1"/>
  </joint>
  <link name="S_L">
    <inertial>
      <origin rpy="0 0 0" xyz="1.1102E-16 0.0254 0.068366"/>
      <mass value="0.22586"/>
      <inertia ixx="0.00034327" ixy="5.1099E-23" ixz="-3.7056E-19" iyy="0.00034804" iyz="1.514E-21" izz="6.7813E-05"/>
    </inertial>
    <visual>
      <origin rpy="0 0 0" xyz="0 0 0"/>
      <geometry>
        <mesh filename="package://simple_car/meshes/S_L.STL"/>
      </geometry>
      <material name="">
        <color rgba="0 0 1 1"/>
      </material>
    </visual>
    <collision>
      <origin rpy="0 0 0" xyz="0 0 0"/>
      <geometry>
        <mesh filename="package://simple_car/meshes/S_L.STL"/>
      </geometry>
    </collision>
  </link>
  <joint name="SL_Joint" type="revolute">
    <origin rpy="1.5708 0 -3.1389" xyz="0.67855 -0.17618 0.36349"/>
    <parent link="base_link"/>
    <child link="S_L"/>
    <axis xyz="0 1 0"/>
    <limit effort="1000" lower="-3.141" upper="3.141" velocity="1000"/>
  </joint>
  <link name="Wheel_FL">
    <inertial>
      <origin rpy="0 0 0" xyz="4.996E-16 -1.6653E-15 -0.038667"/>
      <mass value="2.3167"/>
      <inertia ixx="0.0074731" ixy="-2.6413E-20" ixz="6.7637E-18" iyy="0.0074731" iyz="3.4542E-18" izz="0.012704"/>
    </inertial>
    <visual>
      <origin rpy="0 0 0" xyz="0 0 0"/>
      <geometry>
        <mesh filename="package://simple_car/meshes/Wheel_FL.STL"/>
      </geometry>
      <material name="">
        <color rgba="0 0 0 1"/>
      </material>
    </visual>
    <collision>
      <origin rpy="0 0 0" xyz="0 0 0"/>
      <geometry>
        <mesh filename="package://simple_car/meshes/Wheel_FL.STL"/>
      </geometry>
    </collision>
  </link>
  <joint name="WFL" type="continuous">
    <origin rpy="-3.1416 0 -1.5262" xyz="0 0.0254 0.050233"/>
    <parent link="S_L"/>
    <child link="Wheel_FL"/>
    <axis xyz="0 0 1"/>
  </joint>
  <link name="Wheel_BR">
    <inertial>
      <origin rpy="0 0 0" xyz="0 0 0.0381"/>
      <mass value="2.3167"/>
      <inertia ixx="0.0074731" ixy="-4.3368E-19" ixz="1.5264E-19" iyy="0.0074731" iyz="-3.1795E-20" izz="0.012704"/>
    </inertial>
    <visual>
      <origin rpy="0 0 0" xyz="0 0 0"/>
      <geometry>
        <mesh filename="package://simple_car/meshes/Wheel_BR.STL"/>
      </geometry>
      <material name="">
        <color rgba="0 0 0 1"/>
      </material>
    </visual>
    <collision>
      <origin rpy="0 0 0" xyz="0 0 0"/>
      <geometry>
        <mesh filename="package://simple_car/meshes/Wheel_BR.STL"/>
      </geometry>
    </collision>
  </link>
  <joint name="WBR" type="continuous">
    <origin rpy="1.5708 -1.2878 0" xyz="0.17055 -0.73498 0.38889"/>
    <parent link="base_link"/>
    <child link="Wheel_BR"/>
    <axis xyz="0 0 1"/>
  </joint>
  <link name="Wheel_BL">
    <inertial>
      <origin rpy="0 0 0" xyz="-1.1102E-16 2.7756E-17 0.0381"/>
      <mass value="2.3167"/>
      <inertia ixx="0.0074731" ixy="2.7105E-20" ixz="2.7591E-19" iyy="0.0074731" iyz="-2.9506E-21" izz="0.012704"/>
    </inertial>
    <visual>
      <origin rpy="0 0 0" xyz="0 0 0"/>
      <geometry>
        <mesh filename="package://simple_car/meshes/Wheel_BL.STL"/>
      </geometry>
      <material name="">
        <color rgba="0 0 0 1"/>
      </material>
    </visual>
    <collision>
      <origin rpy="0 0 0" xyz="0 0 0"/>
      <geometry>
        <mesh filename="package://simple_car/meshes/Wheel_BL.STL"/>
      </geometry>
    </collision>
  </link>
  <joint name="WBL" type="continuous">
    <origin rpy="-1.5708 1.5191 -3.1416" xyz="0.17055 -0.049183 0.38889"/>
    <parent link="base_link"/>
    <child link="Wheel_BL"/>
    <axis xyz="0 0 1"/>
  </joint>
  <transmission name="RWD_Right">
    <type>transmission_interface/SimpleTransmission</type>
    <joint name="WBR">
      <hardwareInterface>hardware_interface/VelocityJointInterface</hardwareInterface>
    </joint>
    <actuator name="RWD_Right_Motor">
      <mechanicalReduction>50</mechanicalReduction>
      <hardwareInterface>hardware_interface/VelocityJointInterface</hardwareInterface>
    </actuator>
  </transmission>
  <transmission name="RWD_Left">
    <type>transmission_interface/SimpleTransmission</type>
    <joint name="WBL">
      <hardwareInterface>hardware_interface/VelocityJointInterface</hardwareInterface>
    </joint>
    <actuator name="RWD_Left_Motor">
      <mechanicalReduction>50</mechanicalReduction>
      <hardwareInterface>hardware_interface/VelocityJointInterface</hardwareInterface>
    </actuator>
  </transmission>
  <transmission name="FD_R">
    <type>transmission_interface/SimpleTransmission</type>
    <joint name="WFR">
      <hardwareInterface>hardware_interface/EffortJointInterface</hardwareInterface>
    </joint>
    <actuator name="FD_R_Motor">
      <mechanicalReduction>1</mechanicalReduction>
      <hardwareInterface>hardware_interface/EffortJointInterface</hardwareInterface>
    </actuator>
  </transmission>
  <transmission name="FD_L">
    <type>transmission_interface/SimpleTransmission</type>
    <joint name="WFL">
      <hardwareInterface>hardware_interface/EffortJointInterface</hardwareInterface>
    </joint>
    <actuator name="FD_L_Motor">
      <mechanicalReduction>1</mechanicalReduction>
      <hardwareInterface>hardware_interface/EffortJointInterface</hardwareInterface>
    </actuator>
  </transmission>
  <transmission name="Steer_Left">
    <type>transmission_interface/SimpleTransmission</type>
    <joint name="SL_Joint">
      <hardwareInterface>hardware_interface/PositionJointInterface</hardwareInterface>
    </joint>
    <actuator name="SL_Motor">
      <mechanicalReduction>50</mechanicalReduction>
      <hardwareInterface>hardware_interface/PositionJointInterface</hardwareInterface>
    </actuator>
  </transmission>
  <transmission name="Steer_Right">
    <type>transmission_interface/SimpleTransmission</type>
    <joint name="SR_Joint">
      <hardwareInterface>hardware_interface/PositionJointInterface</hardwareInterface>
    </joint>
    <actuator name="SR_Motor">
      <mechanicalReduction>50</mechanicalReduction>
      <hardwareInterface>hardware_interface/PositionJointInterface</hardwareInterface>
    </actuator>
  </transmission>
  <link name="base_laser">
    <inertial>
      <origin rpy="0 0 0" xyz="-0.00029774 0.0066667 0.00013047"/>
      <mass value="0.15717"/>
      <inertia ixx="6.7885E-05" ixy="-1.3987E-07" ixz="-8.1554E-07" iyy="0.00013173" iyz="-9.0932E-08" izz="7.1972E-05"/>
    </inertial>
    <visual>
      <origin rpy="0 0 0" xyz="0 0 0"/>
      <geometry>
        <mesh filename="package://simple_car/meshes/ydlidar.dae"/>
      </geometry>
      <material name="">
        <color rgba="0.64706 0.61961 0.58824 1"/>
      </material>
    </visual>
    <collision>
      <origin rpy="0 0 0" xyz="0 0 0"/>
      <geometry>
        <mesh filename="package://simple_car/meshes/ydlidar.dae"/>
      </geometry>
    </collision>
  </link>
  <link name="laser_frame">
    <inertial>
      <origin rpy="0 0 0" xyz="-0.00036659 0.00064155 -0.00027052"/>
      <mass value="0.25482"/>
      <inertia ixx="8.9194E-05" ixy="1.8116E-07" ixz="3.6435E-08" iyy="0.00018279" iyz="2.423E-07" izz="0.00011103"/>
    </inertial>
    <visual>
      <origin rpy="0 0 0" xyz="0 0 0"/>
      <geometry>
        <mesh filename="package://simple_car/meshes/ydlidar.dae"/>
      </geometry>
      <material name="">
        <color rgba="0.64706 0.61961 0.58824 1"/>
      </material>
    </visual>
    <collision>
      <origin rpy="0 0 0" xyz="0 0 0"/>
      <geometry>
        <mesh filename="package://simple_car/meshes/ydlidar.dae"/>
      </geometry>
    </collision>
  </link>
  <joint name="laser_joint" type="fixed">
    <origin rpy="0 0 0" xyz="0 0 0.03172"/>
    <parent link="base_laser"/>
    <child link="laser_frame"/>
    <axis xyz="0 0 0"/>
  </joint>
  <!-- Add your gazebo sensors here -->
  <gazebo reference="base_laser">
    <!-- <gravity>true</gravity> -->
    <!-- Gazebo has fixed set of Sensors types. Check them out here <> -->
    <sensor name="laser" type="ray">
      <!-- Add in your sensor characteristics -->
      <pose> 0 0 0 0 0 0 </pose>
      <visualise>true</visualise>
      <update_rate>40</update_rate>
      <!-- <always_on>true</always_on> -->
      <ray>
        <scan>
          <horizontal>
            <samples>720</samples>
            <resolution>1</resolution>
            <min_angle>-1.570796</min_angle>
            <max_angle>1.570796</max_angle>
          </horizontal>
        </scan>
        <range>
          <min>0.10</min>
          <max>30.0</max>
          <resolution>0.01</resolution>
        </range>
        <noise>
          <type>gaussian</type>
          <mean>0.0</mean>
          <stddev>0.01</stddev>
        </noise>
      </ray>
      <plugin filename="libgazebo_ros_laser.so" name="gazebo_ros_head_hokuyo_controller">
        <!-- Use topic name as /my_robot/scan -->
        <topicName>/simple_car/scan</topicName>
        <frameName>laser_frame</frameName>
      </plugin>
    </sensor>
  </gazebo>
  <!--  Gazebo plugin for control here is already added for you -->
  <gazebo>
    <plugin filename="libgazebo_ros_control.so" name="gazebo_ros_control">
      <robotNamespace>/simple_car</robotNamespace>
      <robotSimType>gazebo_ros_control/DefaultRobotHWSim</robotSimType>
      <legacyModeNS>true</legacyModeNS>
    </plugin>
  </gazebo>
  <!-- Create a joint between your robot and sensor -->
  <joint name="laser_frame" type="fixed">
    <parent link="base_link"/>
    <child link="base_laser"/>
    <origin rpy="0.0 0.0 3.141" xyz="0 0 0.1991"/>
  </joint>
</robot>
