<?xml version="1.0" ?>
<!-- =================================================================================== -->
<!-- |    This document was autogenerated by xacro from simple_car_1_integration.urdf.xacro | -->
<!-- |    EDITING THIS FILE BY HAND IS NOT RECOMMENDED                                 | -->
<!-- =================================================================================== -->
<!-- Name your robot here -->
<robot name="simple_car_1">
  <link name="dummy">
  </link>
  <joint name="dummy_joint" type="fixed">
    <parent link="dummy"/>
    <child link="base_link"/>
  </joint>
  <link name="base_link">
    <inertial>
      <origin rpy="0 0 0" xyz="-0.00332460565658627 1.58676196071461E-08 0.041560079075296"/>
      <mass value="42.8861348655346"/>
      <inertia ixx="1.00588271538571" ixy="-1.46408273025479E-07" ixz="-0.0167901751526591" iyy="1.73667960585585" iyz="5.80765070709865E-08" izz="2.43688572871735"/>
    </inertial>
    <visual>
      <origin rpy="0 0 0" xyz="0 0 0"/>
      <geometry>
        <mesh filename="package://simple_car_1/meshes/base_link.STL"/>
      </geometry>
      <material name="">
        <color rgba="0.792156862745098 0.819607843137255 0.933333333333333 1"/>
      </material>
    </visual>
    <collision>
      <origin rpy="0 0 0" xyz="0 0 0"/>
      <geometry>
        <mesh filename="package://simple_car_1/meshes/base_link.STL"/>
      </geometry>
    </collision>
  </link>
  <link name="S_R">
    <inertial>
      <origin rpy="0 0 0" xyz="0.0683552158020454 0.00119688729774237 -2.83106871279415E-15"/>
      <mass value="0.225860858102532"/>
      <inertia ixx="6.78977829710827E-05" ixy="-4.82166445850817E-06" ixz="-3.09292498343065E-19" iyy="0.000343182570643455" iyz="-5.50199363756215E-21" izz="0.000348044864929136"/>
    </inertial>
    <visual>
      <origin rpy="0 0 0" xyz="0 0 0"/>
      <geometry>
        <mesh filename="package://simple_car_1/meshes/S_R.STL"/>
      </geometry>
      <material name="">
        <color rgba="0 0 1 1"/>
      </material>
    </visual>
    <collision>
      <origin rpy="0 0 0" xyz="0 0 0"/>
      <geometry>
        <mesh filename="package://simple_car_1/meshes/S_R.STL"/>
      </geometry>
    </collision>
  </link>
  <joint name="SR_Joint" type="revolute">
    <origin rpy="0 0 -1.59384943873931" xyz="0.254000000000007 -0.254 -0.0762000000000029"/>
    <parent link="base_link"/>
    <child link="S_R"/>
    <axis xyz="0 0 1"/>
    <limit effort="1000" lower="-1" upper="1" velocity="1000"/>
  </joint>
  <link name="Wheel_FR">
    <inertial>
      <origin rpy="0 0 0" xyz="-0.0011093843075205 0.00109160341947936 0.0380458860342316"/>
      <mass value="2.31666659443376"/>
      <inertia ixx="0.00747391772869096" ixy="-8.01571740731554E-07" ixz="-6.52698636700994E-05" iyy="0.00747389182470713" iyz="6.42237373359677E-05" izz="0.0127026719178023"/>
    </inertial>
    <visual>
      <origin rpy="0 0 0" xyz="0 0 0"/>
      <geometry>
        <mesh filename="package://simple_car_1/meshes/Wheel_FR.STL"/>
      </geometry>
      <material name="">
        <color rgba="0 0 0 1"/>
      </material>
    </visual>
    <collision>
      <origin rpy="0 0 0" xyz="0 0 0"/>
      <geometry>
        <mesh filename="package://simple_car_1/meshes/Wheel_FR.STL"/>
      </geometry>
    </collision>
  </link>
  <joint name="WFR" type="continuous">
    <origin rpy="-1.5707963267949 0.777319744318453 -1.5707963267949" xyz="0.0508404890096035 0 0"/>
    <parent link="S_R"/>
    <child link="Wheel_FR"/>
    <axis xyz="0 0 1"/>
  </joint>
  <link name="S_L">
    <inertial>
      <origin rpy="0 0 0" xyz="0.0683656830546928 -3.80399174700896E-05 0"/>
      <mass value="0.225860858102532"/>
      <inertia ixx="6.78134417911135E-05" ixy="1.53267400130195E-07" ixz="4.13476612842137E-22" iyy="0.000343266911823424" iyz="-4.31100267529608E-23" izz="0.000348044864929136"/>
    </inertial>
    <visual>
      <origin rpy="0 0 0" xyz="0 0 0"/>
      <geometry>
        <mesh filename="package://simple_car_1/meshes/S_L.STL"/>
      </geometry>
      <material name="">
        <color rgba="0 0 1 1"/>
      </material>
    </visual>
    <collision>
      <origin rpy="0 0 0" xyz="0 0 0"/>
      <geometry>
        <mesh filename="package://simple_car_1/meshes/S_L.STL"/>
      </geometry>
    </collision>
  </link>
  <joint name="SL_Joint" type="revolute">
    <origin rpy="0 0 1.57346784124955" xyz="0.25399999999996 0.253999999999836 -0.0762"/>
    <parent link="base_link"/>
    <child link="S_L"/>
    <axis xyz="0 0 1"/>
    <limit effort="1000" lower="-1" upper="1" velocity="1000"/>
  </joint>
  <link name="Wheel_FL">
    <inertial>
      <origin rpy="0 0 0" xyz="-2.20509283793691E-06 4.94164054692936E-05 -0.0386664950496765"/>
      <mass value="2.31666659443376"/>
      <inertia ixx="0.00747310310354289" ixy="-7.21262781980466E-11" ixz="1.29754988760008E-07" iyy="0.0074731047166833" iyz="-2.90782547822008E-06" izz="0.0127042736509742"/>
    </inertial>
    <visual>
      <origin rpy="0 0 0" xyz="0 0 0"/>
      <geometry>
        <mesh filename="package://simple_car_1/meshes/Wheel_FL.STL"/>
      </geometry>
      <material name="">
        <color rgba="0 0 0 1"/>
      </material>
    </visual>
    <collision>
      <origin rpy="0 0 0" xyz="0 0 0"/>
      <geometry>
        <mesh filename="package://simple_car_1/meshes/Wheel_FL.STL"/>
      </geometry>
    </collision>
  </link>
  <joint name="WFL" type="continuous">
    <origin rpy="-1.57079632679487 1.52620322090237 1.57079632679492" xyz="0.0502334911887114 0 0"/>
    <parent link="S_L"/>
    <child link="Wheel_FL"/>
    <axis xyz="0 0 1"/>
  </joint>
  <link name="Wheel_BR">
    <inertial>
      <origin rpy="0 0 0" xyz="0 0 0.0381000000000001"/>
      <mass value="2.31666659443376"/>
      <inertia ixx="0.00747310310032443" ixy="-4.33680868994202E-19" ixz="1.52641837812297E-19" iyy="0.00747310310032443" iyz="-3.17947464336863E-20" izz="0.0127042752705515"/>
    </inertial>
    <visual>
      <origin rpy="0 0 0" xyz="0 0 0"/>
      <geometry>
        <mesh filename="package://simple_car_1/meshes/Wheel_BR.STL"/>
      </geometry>
      <material name="">
        <color rgba="0 0 0 1"/>
      </material>
    </visual>
    <collision>
      <origin rpy="0 0 0" xyz="0 0 0"/>
      <geometry>
        <mesh filename="package://simple_car_1/meshes/Wheel_BR.STL"/>
      </geometry>
    </collision>
  </link>
  <joint name="WBR" type="continuous">
    <origin rpy="1.5707963267949 -1.28782237474481 0" xyz="-0.254 -0.3048 -0.0762000000000036"/>
    <parent link="base_link"/>
    <child link="Wheel_BR"/>
    <axis xyz="0 0 1"/>
  </joint>
  <link name="Wheel_BL">
    <inertial>
      <origin rpy="0 0 0" xyz="-1.11022302462516E-16 2.77555756156289E-17 0.0381"/>
      <mass value="2.31666659443376"/>
      <inertia ixx="0.00747310310032442" ixy="2.71050543121376E-20" ixz="2.75908916846999E-19" iyy="0.00747310310032442" iyz="-2.95060764470901E-21" izz="0.0127042752705515"/>
    </inertial>
    <visual>
      <origin rpy="0 0 0" xyz="0 0 0"/>
      <geometry>
        <mesh filename="package://simple_car_1/meshes/Wheel_BL.STL"/>
      </geometry>
      <material name="">
        <color rgba="0 0 0 1"/>
      </material>
    </visual>
    <collision>
      <origin rpy="0 0 0" xyz="0 0 0"/>
      <geometry>
        <mesh filename="package://simple_car_1/meshes/Wheel_BL.STL"/>
      </geometry>
    </collision>
  </link>
  <joint name="WBL" type="continuous">
    <origin rpy="-1.5707963267949 1.51907124574579 3.14159265358979" xyz="-0.254 0.381 -0.0762000000000034"/>
    <parent link="base_link"/>
    <child link="Wheel_BL"/>
    <axis xyz="0 0 1"/>
  </joint>
  <transmission name="RWD_Right">
    <type>transmission_interface/SimpleTransmission</type>
    <joint name="WBR">
      <hardwareInterface>hardware_interface/VelocityJointInterface</hardwareInterface>
    </joint>
    <actuator name="RWD_Right_Motor">
      <mechanicalReduction>50</mechanicalReduction>
      <hardwareInterface>hardware_interface/VelocityJointInterface</hardwareInterface>
    </actuator>
  </transmission>
  <transmission name="RWD_Left">
    <type>transmission_interface/SimpleTransmission</type>
    <joint name="WBL">
      <hardwareInterface>hardware_interface/VelocityJointInterface</hardwareInterface>
    </joint>
    <actuator name="RWD_Left_Motor">
      <mechanicalReduction>50</mechanicalReduction>
      <hardwareInterface>hardware_interface/VelocityJointInterface</hardwareInterface>
    </actuator>
  </transmission>
  <transmission name="FD_R">
    <type>transmission_interface/SimpleTransmission</type>
    <joint name="WFR">
      <hardwareInterface>hardware_interface/EffortJointInterface</hardwareInterface>
    </joint>
    <actuator name="FD_R_Motor">
      <mechanicalReduction>1</mechanicalReduction>
      <hardwareInterface>hardware_interface/EffortJointInterface</hardwareInterface>
    </actuator>
  </transmission>
  <transmission name="FD_L">
    <type>transmission_interface/SimpleTransmission</type>
    <joint name="WFL">
      <hardwareInterface>hardware_interface/EffortJointInterface</hardwareInterface>
    </joint>
    <actuator name="FD_L_Motor">
      <mechanicalReduction>1</mechanicalReduction>
      <hardwareInterface>hardware_interface/EffortJointInterface</hardwareInterface>
    </actuator>
  </transmission>
  <transmission name="Steer_Left">
    <type>transmission_interface/SimpleTransmission</type>
    <joint name="SL_Joint">
      <hardwareInterface>hardware_interface/PositionJointInterface</hardwareInterface>
    </joint>
    <actuator name="SL_Motor">
      <mechanicalReduction>50</mechanicalReduction>
      <hardwareInterface>hardware_interface/PositionJointInterface</hardwareInterface>
    </actuator>
  </transmission>
  <transmission name="Steer_Right">
    <type>transmission_interface/SimpleTransmission</type>
    <joint name="SR_Joint">
      <hardwareInterface>hardware_interface/PositionJointInterface</hardwareInterface>
    </joint>
    <actuator name="SR_Motor">
      <mechanicalReduction>50</mechanicalReduction>
      <hardwareInterface>hardware_interface/PositionJointInterface</hardwareInterface>
    </actuator>
  </transmission>
  <link name="base_laser">
    <inertial>
      <origin rpy="0 0 0" xyz="-0.00029774 0.0066667 0.00013047"/>
      <mass value="0.15717"/>
      <inertia ixx="6.7885E-05" ixy="-1.3987E-07" ixz="-8.1554E-07" iyy="0.00013173" iyz="-9.0932E-08" izz="7.1972E-05"/>
    </inertial>
    <visual>
      <origin rpy="0 0 0" xyz="0 0 0"/>
      <geometry>
        <mesh filename="package://simple_car/meshes/ydlidar.dae"/>
      </geometry>
      <material name="">
        <color rgba="0.64706 0.61961 0.58824 1"/>
      </material>
    </visual>
    <collision>
      <origin rpy="0 0 0" xyz="0 0 0"/>
      <geometry>
        <mesh filename="package://simple_car/meshes/ydlidar.dae"/>
      </geometry>
    </collision>
  </link>
  <link name="laser_frame">
    <inertial>
      <origin rpy="0 0 0" xyz="-0.00036659 0.00064155 -0.00027052"/>
      <mass value="0.25482"/>
      <inertia ixx="8.9194E-05" ixy="1.8116E-07" ixz="3.6435E-08" iyy="0.00018279" iyz="2.423E-07" izz="0.00011103"/>
    </inertial>
    <visual>
      <origin rpy="0 0 0" xyz="0 0 0"/>
      <geometry>
        <mesh filename="package://simple_car/meshes/ydlidar.dae"/>
      </geometry>
      <material name="">
        <color rgba="0.64706 0.61961 0.58824 1"/>
      </material>
    </visual>
    <collision>
      <origin rpy="0 0 0" xyz="0 0 0"/>
      <geometry>
        <mesh filename="package://simple_car/meshes/ydlidar.dae"/>
      </geometry>
    </collision>
  </link>
  <joint name="laser_joint" type="fixed">
    <origin rpy="0 0 0" xyz="0 0 0.03172"/>
    <parent link="base_laser"/>
    <child link="laser_frame"/>
    <axis xyz="0 0 0"/>
  </joint>
  <!-- Add your gazebo sensors here -->
  <gazebo reference="base_laser">
    <!-- <gravity>true</gravity> -->
    <!-- Gazebo has fixed set of Sensors types. Check them out here <> -->
    <sensor name="laser" type="ray">
      <!-- Add in your sensor characteristics -->
      <pose> 0 0 0 0 0 0 </pose>
      <visualise>true</visualise>
      <update_rate>40</update_rate>
      <!-- <always_on>true</always_on> -->
      <ray>
        <scan>
          <horizontal>
            <samples>720</samples>
            <resolution>1</resolution>
            <min_angle>-1.570796</min_angle>
            <max_angle>1.570796</max_angle>
          </horizontal>
        </scan>
        <range>
          <min>0.10</min>
          <max>30.0</max>
          <resolution>0.01</resolution>
        </range>
        <noise>
          <type>gaussian</type>
          <mean>0.0</mean>
          <stddev>0.01</stddev>
        </noise>
      </ray>
      <plugin filename="libgazebo_ros_laser.so" name="gazebo_ros_head_hokuyo_controller">
        <!-- Use topic name as /my_robot/scan -->
        <topicName>/simple_car_1/scan</topicName>
        <frameName>laser_frame</frameName>
      </plugin>
    </sensor>
  </gazebo>
  <!--  Gazebo plugin for control here is already added for you -->
  <gazebo>
    <plugin filename="libgazebo_ros_control.so" name="gazebo_ros_control">
      <robotNamespace>/simple_car_1</robotNamespace>
      <robotSimType>gazebo_ros_control/DefaultRobotHWSim</robotSimType>
      <legacyModeNS>true</legacyModeNS>
    </plugin>
  </gazebo>
  <!-- Create a joint between your robot and sensor -->
  <joint name="laser_frame" type="fixed">
    <parent link="base_link"/>
    <child link="base_laser"/>
    <origin rpy="0.0 0.0 3.141" xyz="0 0 0.1"/>
  </joint>
</robot>
