<?xml version="1.0" encoding="utf-8"?>
<!-- This URDF was automatically created by SolidWorks to URDF Exporter! Originally created by Stephen Brawner (brawner@gmail.com) 
     Commit Version: 1.6.0-1-g15f4949  Build Version: 1.6.7594.29634
     For more information, please see http://wiki.ros.org/sw_urdf_exporter -->
<robot
  name="simple_car">
  <link
    name="base_link">
    <inertial>
      <origin
        xyz="0.42123 0.50665 0.43018"
        rpy="0 0 0" />
      <mass
        value="42.886" />
      <inertia
        ixx="1.0059"
        ixy="-0.01679"
        ixz="1.4641E-07"
        iyy="2.4369"
        iyz="-5.8077E-08"
        izz="1.7367" />
    </inertial>
    <visual>
      <origin
        xyz="0 0 0"
        rpy="0 0 0" />
      <geometry>
        <mesh
          filename="package://simple_car/meshes/base_link.STL" />
      </geometry>
      <material
        name="">
        <color
          rgba="0.79216 0.81961 0.93333 1" />
      </material>
    </visual>
    <collision>
      <origin
        xyz="0 0 0"
        rpy="0 0 0" />
      <geometry>
        <mesh
          filename="package://simple_car/meshes/base_link.STL" />
      </geometry>
    </collision>
  </link>
  <link
    name="S_R">
    <inertial>
      <origin
        xyz="3.6637E-15 0.0254 0.068366"
        rpy="0 0 0" />
      <mass
        value="0.22586" />
      <inertia
        ixx="0.00034327"
        ixy="6.532E-24"
        ixz="-8.5053E-19"
        iyy="0.00034804"
        iyz="7.0833E-22"
        izz="6.7813E-05" />
    </inertial>
    <visual>
      <origin
        xyz="0 0 0"
        rpy="0 0 0" />
      <geometry>
        <mesh
          filename="package://simple_car/meshes/S_R.STL" />
      </geometry>
      <material
        name="">
        <color
          rgba="0 0 1 1" />
      </material>
    </visual>
    <collision>
      <origin
        xyz="0 0 0"
        rpy="0 0 0" />
      <geometry>
        <mesh
          filename="package://simple_car/meshes/S_R.STL" />
      </geometry>
    </collision>
  </link>
  <joint
    name="SR_Joint"
    type="revolute">
    <origin
      xyz="0.67855 -0.68418 0.36349"
      rpy="1.5708 0 -0.023053" />
    <parent
      link="base_link" />
    <child
      link="S_R" />
    <axis
      xyz="0 1 0" />
    <limit
      lower="-3.141"
      upper="3.141"
      effort="1000"
      velocity="1000" />
  </joint>
  <link
    name="Wheel_FR">
    <inertial>
      <origin
        xyz="2.3315E-15 -2.387E-15 0.03806"
        rpy="0 0 0" />
      <mass
        value="2.3167" />
      <inertia
        ixx="0.0074731"
        ixy="3.5893E-19"
        ixz="-1.1316E-17"
        iyy="0.0074731"
        iyz="-4.391E-18"
        izz="0.012704" />
    </inertial>
    <visual>
      <origin
        xyz="0 0 0"
        rpy="0 0 0" />
      <geometry>
        <mesh
          filename="package://simple_car/meshes/Wheel_FR.STL" />
      </geometry>
      <material
        name="">
        <color
          rgba="0 0 0 1" />
      </material>
    </visual>
    <collision>
      <origin
        xyz="0 0 0"
        rpy="0 0 0" />
      <geometry>
        <mesh
          filename="package://simple_car/meshes/Wheel_FR.STL" />
      </geometry>
    </collision>
  </link>
  <joint
    name="WFR"
    type="continuous">
    <origin
      xyz="0 0.0254 0.05084"
      rpy="0 0 -2.3643" />
    <parent
      link="S_R" />
    <child
      link="Wheel_FR" />
    <axis
      xyz="0 0 1" />
  </joint>
  <link
    name="S_L">
    <inertial>
      <origin
        xyz="1.1102E-16 0.0254 0.068366"
        rpy="0 0 0" />
      <mass
        value="0.22586" />
      <inertia
        ixx="0.00034327"
        ixy="5.1099E-23"
        ixz="-3.7056E-19"
        iyy="0.00034804"
        iyz="1.514E-21"
        izz="6.7813E-05" />
    </inertial>
    <visual>
      <origin
        xyz="0 0 0"
        rpy="0 0 0" />
      <geometry>
        <mesh
          filename="package://simple_car/meshes/S_L.STL" />
      </geometry>
      <material
        name="">
        <color
          rgba="0 0 1 1" />
      </material>
    </visual>
    <collision>
      <origin
        xyz="0 0 0"
        rpy="0 0 0" />
      <geometry>
        <mesh
          filename="package://simple_car/meshes/S_L.STL" />
      </geometry>
    </collision>
  </link>
  <joint
    name="SL_Joint"
    type="revolute">
    <origin
      xyz="0.67855 -0.17618 0.36349"
      rpy="1.5708 0 -3.1389" />
    <parent
      link="base_link" />
    <child
      link="S_L" />
    <axis
      xyz="0 1 0" />
    <limit
      lower="-3.141"
      upper="3.141"
      effort="1000"
      velocity="1000" />
  </joint>
  <link
    name="Wheel_FL">
    <inertial>
      <origin
        xyz="4.996E-16 -1.6653E-15 -0.038667"
        rpy="0 0 0" />
      <mass
        value="2.3167" />
      <inertia
        ixx="0.0074731"
        ixy="-2.6413E-20"
        ixz="6.7637E-18"
        iyy="0.0074731"
        iyz="3.4542E-18"
        izz="0.012704" />
    </inertial>
    <visual>
      <origin
        xyz="0 0 0"
        rpy="0 0 0" />
      <geometry>
        <mesh
          filename="package://simple_car/meshes/Wheel_FL.STL" />
      </geometry>
      <material
        name="">
        <color
          rgba="0 0 0 1" />
      </material>
    </visual>
    <collision>
      <origin
        xyz="0 0 0"
        rpy="0 0 0" />
      <geometry>
        <mesh
          filename="package://simple_car/meshes/Wheel_FL.STL" />
      </geometry>
    </collision>
  </link>
  <joint
    name="WFL"
    type="continuous">
    <origin
      xyz="0 0.0254 0.050233"
      rpy="-3.1416 0 -1.5262" />
    <parent
      link="S_L" />
    <child
      link="Wheel_FL" />
    <axis
      xyz="0 0 1" />
  </joint>
  <link
    name="Wheel_BR">
    <inertial>
      <origin
        xyz="0 0 0.0381"
        rpy="0 0 0" />
      <mass
        value="2.3167" />
      <inertia
        ixx="0.0074731"
        ixy="-4.3368E-19"
        ixz="1.5264E-19"
        iyy="0.0074731"
        iyz="-3.1795E-20"
        izz="0.012704" />
    </inertial>
    <visual>
      <origin
        xyz="0 0 0"
        rpy="0 0 0" />
      <geometry>
        <mesh
          filename="package://simple_car/meshes/Wheel_BR.STL" />
      </geometry>
      <material
        name="">
        <color
          rgba="0 0 0 1" />
      </material>
    </visual>
    <collision>
      <origin
        xyz="0 0 0"
        rpy="0 0 0" />
      <geometry>
        <mesh
          filename="package://simple_car/meshes/Wheel_BR.STL" />
      </geometry>
    </collision>
  </link>
  <joint
    name="WBR"
    type="continuous">
    <origin
      xyz="0.17055 -0.73498 0.38889"
      rpy="1.5708 -1.2878 0" />
    <parent
      link="base_link" />
    <child
      link="Wheel_BR" />
    <axis
      xyz="0 0 1" />
  </joint>
  <link
    name="Wheel_BL">
    <inertial>
      <origin
        xyz="-1.1102E-16 2.7756E-17 0.0381"
        rpy="0 0 0" />
      <mass
        value="2.3167" />
      <inertia
        ixx="0.0074731"
        ixy="2.7105E-20"
        ixz="2.7591E-19"
        iyy="0.0074731"
        iyz="-2.9506E-21"
        izz="0.012704" />
    </inertial>
    <visual>
      <origin
        xyz="0 0 0"
        rpy="0 0 0" />
      <geometry>
        <mesh
          filename="package://simple_car/meshes/Wheel_BL.STL" />
      </geometry>
      <material
        name="">
        <color
          rgba="0 0 0 1" />
      </material>
    </visual>
    <collision>
      <origin
        xyz="0 0 0"
        rpy="0 0 0" />
      <geometry>
        <mesh
          filename="package://simple_car/meshes/Wheel_BL.STL" />
      </geometry>
    </collision>
  </link>
  <joint
    name="WBL"
    type="continuous">
    <origin
      xyz="0.17055 -0.049183 0.38889"
      rpy="-1.5708 1.5191 -3.1416" />
    <parent
      link="base_link" />
    <child
      link="Wheel_BL" />
    <axis
      xyz="0 0 1" />
  </joint>
</robot>